<?xml version="1.0" ?>
<!-- =================================================================================== -->
<!-- |    This document was autogenerated by xacro from darko_robot.urdf.xacro         | -->
<!-- |    EDITING THIS FILE BY HAND IS NOT RECOMMENDED                                 | -->
<!-- =================================================================================== -->
<!-- This config is based upon: summit_xl_description/robots/summit_xls_std.urdf -->
<robot name="summit_xl">
  <!-- ***************** -->
  <!-- Imported elements -->
  <!-- ***************** -->
  <!-- First we import all possible elements defined in the urdf.xacro files. All these elements are defined as macro:xacros -->
  <gazebo reference="base_footprint">
    <material>Gazebo/Green</material>
  </gazebo>
  <!-- in kg-->
  <!-- in kg-->
  <!-- source en.wikipedia.org/wiki/List_of_moments_of_inertia-->
  <!-- This file unifies all sensors that can be used on simulation, defined as xacro:macros -->
  <!-- Includes -->
  <!-- source en.wikipedia.org/wiki/List_of_moments_of_inertia-->
  <!-- TODO: All values in here were copied from Kinect v2 and need fine-tuning! -->
  <!-- source en.wikipedia.org/wiki/List_of_moments_of_inertia-->
  <!-- source en.wikipedia.org/wiki/List_of_moments_of_inertia-->
  <!-- source en.wikipedia.org/wiki/List_of_moments_of_inertia-->
  <!-- source en.wikipedia.org/wiki/List_of_moments_of_inertia-->
  <!-- source en.wikipedia.org/wiki/List_of_moments_of_inertia-->
  <!-- source en.wikipedia.org/wiki/List_of_moments_of_inertia-->
  <!-- source en.wikipedia.org/wiki/List_of_moments_of_inertia-->
  <!-- source en.wikipedia.org/wiki/List_of_moments_of_inertia-->
  <!-- source en.wikipedia.org/wiki/List_of_moments_of_inertia-->
  <!-- Disabled because Panda simulator introduces its own, extended version of ros_control -->
  <!-- <xacro:ros_control/> -->
  <!-- *************** -->
  <!-- Robots Elements -->
  <!-- *************** -->
  <!-- Here we create the robot elements using the xacro:macros imported at the beggining of this file -->
  <link name="darko/base_footprint">
    <visual>
      <origin rpy="0 0 0" xyz="0 0 0"/>
      <geometry>
        <box size="0.001 0.001 0.001"/>
      </geometry>
    </visual>
  </link>
  <joint name="darko/base_footprint_joint" type="fixed">
    <origin rpy="0 0 0" xyz="0 0 0.127"/>
    <!-- ${wheel_radius} property must be defined inside wheel description -->
    <parent link="darko/base_footprint"/>
    <child link="darko/base_link"/>
  </joint>
  <!-- BASE_LINK -->
  <link name="darko/base_link">
    <inertial>
      <mass value="125.0"/>
      <origin xyz="0 0 0"/>
      <inertia ixx="1.391" ixy="0.004" ixz="0.0" iyy="6.853" iyz="0.0" izz="6.125"/>
    </inertial>
    <visual>
      <origin rpy="0 0 0" xyz="0 0 0"/>
      <geometry>
        <mesh filename="package://summit_xl_description/meshes/bases/xls/summit_xlsk_oem.stl"/>
      </geometry>
      <material name="black">
        <color rgba="0.0 0.0 0.0 1"/>
      </material>
    </visual>
    <collision>
      <origin rpy="0 0 0 " xyz="0 0 0"/>
      <geometry>
        <mesh filename="package://summit_xl_description/meshes/bases/xls/summit_xlsk_oem.dae"/>
      </geometry>
      <!-- better a box than a mesh for collision -->
      <!--<origin xyz="0 0 0.381" rpy="0 0 0"/>-->
      <!--<geometry>-->
      <!--<box size="0.719 0.578 0.363"/>-->
      <!--</geometry>-->
    </collision>
  </link>
  <gazebo reference="darko/base_link">
    <material>Gazebo/Black</material>
  </gazebo>
  <!-- CHAPAS INOX TAPAS -->
  <link name="darko/base_chapa">
    <visual>
      <origin rpy="0 0 0" xyz="0 0 0"/>
      <geometry>
        <mesh filename="package://summit_xl_description/meshes/bases/xls/summit_xls_chapas_inox_tapas.stl"/>
      </geometry>
      <material name="darkgrey">
        <color rgba="0.5 0.5 0.5 1"/>
      </material>
    </visual>
  </link>
  <joint name="darko/base_tapa_joint" type="fixed">
    <origin rpy="0 0 0" xyz="0.0 0 0.38062"/>
    <parent link="darko/base_link"/>
    <child link="darko/base_chapa"/>
  </joint>
  <!-- LOGO ROBOTNIK IZQUIERDO -->
  <link name="darko/base_logo_left">
    <visual>
      <origin rpy="0 0 0" xyz="0 0 0"/>
      <geometry>
        <mesh filename="package://summit_xl_description/meshes/bases/xls/robotnik_logo_chasis.stl"/>
      </geometry>
      <material name="darkgrey">
        <color rgba="0.5 0.5 0.5 1"/>
      </material>
    </visual>
  </link>
  <joint name="darko/base_logo_left_joint" type="fixed">
    <origin rpy="0 0 0" xyz="0.0 0.28931 0.29062"/>
    <parent link="darko/base_link"/>
    <child link="darko/base_logo_left"/>
  </joint>
  <!-- LOGO ROBOTNIK DERECHO -->
  <link name="darko/base_logo_right">
    <visual>
      <origin rpy="0 0 0" xyz="0 0 0"/>
      <geometry>
        <mesh filename="package://summit_xl_description/meshes/bases/xls/robotnik_logo_chasis.stl"/>
      </geometry>
      <material name="darkgrey">
        <color rgba="0.5 0.5 0.5 1"/>
      </material>
    </visual>
  </link>
  <joint name="darko/base_logo_right_joint" type="fixed">
    <origin rpy="0 0 3.141592653589793" xyz="0.0 -0.28931 0.29062"/>
    <parent link="darko/base_link"/>
    <child link="darko/base_logo_right"/>
  </joint>
  <!-- LOGO ROBOTNIK FRONTAL -->
  <link name="darko/base_logo_front">
    <visual>
      <origin rpy="0 0 0" xyz="0 0 0"/>
      <geometry>
        <mesh filename="package://summit_xl_description/meshes/bases/xls/robotnik_logo_chasis.stl"/>
      </geometry>
      <material name="darkgrey">
        <color rgba="0.5 0.5 0.5 1"/>
      </material>
    </visual>
  </link>
  <joint name="darko/base_logo_front_joint" type="fixed">
    <origin rpy="0 0 -1.5707963267948966" xyz="0.345 0.0 0.0"/>
    <parent link="darko/base_link"/>
    <child link="darko/base_logo_front"/>
  </joint>
  <!-- LOGO ROBOTNIK TRASERO -->
  <link name="darko/base_logo_rear">
    <visual>
      <origin rpy="0 0 0" xyz="0 0 0"/>
      <geometry>
        <mesh filename="package://summit_xl_description/meshes/bases/xls/robotnik_logo_chasis.stl"/>
      </geometry>
      <material name="darkgrey">
        <color rgba="0.5 0.5 0.5 1"/>
      </material>
    </visual>
  </link>
  <joint name="darko/base_logo_rear_joint" type="fixed">
    <origin rpy="0 0 1.5707963267948966" xyz="-0.345 0.0 0.0"/>
    <parent link="darko/base_link"/>
    <child link="darko/base_logo_rear"/>
  </joint>
  <!-- DOCKING CONTACT -->
  <link name="darko/base_docking_contact">
    </link>
  <joint name="darko/base_docking_joint" type="fixed">
    <origin rpy="0 0 0" xyz="0.35 0 0.09"/>
    <parent link="darko/base_link"/>
    <child link="darko/base_docking_contact"/>
  </joint>
  <joint name="darko/front_right_wheel_joint" type="continuous">
    <parent link="darko/base_link"/>
    <child link="darko/front_right_wheel_link"/>
    <origin rpy="0 0 0" xyz="0.2225 -0.2675 0.0"/>
    <axis rpy="0 0 0" xyz="0 1 0"/>
    <limit effort="100" velocity="100"/>
    <joint_properties damping="0.0" friction="0.0"/>
  </joint>
  <link name="darko/front_right_wheel_link">
    <visual>
      <origin rpy="0 0 0" xyz="0 0 0"/>
      <geometry>
        <mesh filename="package://summit_xl_description/meshes/wheels/omni_wheel_2.dae"/>
      </geometry>
      <material name="darkgrey">
        <color rgba="0.2 0.2 0.2 1"/>
      </material>
    </visual>
    <collision>
      <origin rpy="1.5707963267948966 0 0" xyz="0 0 0"/>
      <geometry>
        <!--sphere radius="${omni_wheel_radius}" /-->
        <!--
          <xacro:if value="${reflect}">
              <mesh filename="package://summit_xl_description/meshes/wheels/omni_wheel_1.dae" />
          </xacro:if>
          <xacro:unless value="${reflect}">
              <mesh filename="package://summit_xl_description/meshes/wheels/omni_wheel_2.dae" />
					</xacro:unless>
-->
        <cylinder length="0.087" radius="0.127"/>
        <!-- sphere radius="${omni_wheel_radius}"/-->
      </geometry>
    </collision>
    <inertial>
      <mass value="6.5"/>
      <origin xyz="0 0 0"/>
      <inertia ixx="0.0303095" ixy="0" ixz="0" iyy="0.05241925" iyz="0" izz="0.0303095"/>
    </inertial>
  </link>
  <!-- Transmission is important to link the joints and the controller (see summit_xl_control/config/summit_xl_control.yaml)-->
  <transmission name="darko/front_right_wheel_joint_trans">
    <type>transmission_interface/SimpleTransmission</type>
    <joint name="darko/front_right_wheel_joint">
      <hardwareInterface>hardware_interface/VelocityJointInterface</hardwareInterface>
    </joint>
    <actuator name="darko/front_right_wheel_joint_motor">
      <mechanicalReduction>1</mechanicalReduction>
    </actuator>
  </transmission>
  <gazebo reference="darko/front_right_wheel_link">
    <mu1 value="0.0"/>
    <mu2 value="0.0"/>
    <kp value="10000000.0"/>
    <kd value="1.0"/>
    <fdir1 value="1 0 0"/>
    <turnGravityOff>false</turnGravityOff>
  </gazebo>
  <joint name="darko/front_left_wheel_joint" type="continuous">
    <parent link="darko/base_link"/>
    <child link="darko/front_left_wheel_link"/>
    <origin rpy="0 0 0" xyz="0.2225 0.2675 0.0"/>
    <axis rpy="0 0 0" xyz="0 1 0"/>
    <limit effort="100" velocity="100"/>
    <joint_properties damping="0.0" friction="0.0"/>
  </joint>
  <link name="darko/front_left_wheel_link">
    <visual>
      <origin rpy="0 0 0" xyz="0 0 0"/>
      <geometry>
        <mesh filename="package://summit_xl_description/meshes/wheels/omni_wheel_1.dae"/>
      </geometry>
      <material name="darkgrey">
        <color rgba="0.2 0.2 0.2 1"/>
      </material>
    </visual>
    <collision>
      <origin rpy="1.5707963267948966 0 0" xyz="0 0 0"/>
      <geometry>
        <!--sphere radius="${omni_wheel_radius}" /-->
        <!--
          <xacro:if value="${reflect}">
              <mesh filename="package://summit_xl_description/meshes/wheels/omni_wheel_1.dae" />
          </xacro:if>
          <xacro:unless value="${reflect}">
              <mesh filename="package://summit_xl_description/meshes/wheels/omni_wheel_2.dae" />
					</xacro:unless>
-->
        <cylinder length="0.087" radius="0.127"/>
        <!-- sphere radius="${omni_wheel_radius}"/-->
      </geometry>
    </collision>
    <inertial>
      <mass value="6.5"/>
      <origin xyz="0 0 0"/>
      <inertia ixx="0.0303095" ixy="0" ixz="0" iyy="0.05241925" iyz="0" izz="0.0303095"/>
    </inertial>
  </link>
  <!-- Transmission is important to link the joints and the controller (see summit_xl_control/config/summit_xl_control.yaml)-->
  <transmission name="darko/front_left_wheel_joint_trans">
    <type>transmission_interface/SimpleTransmission</type>
    <joint name="darko/front_left_wheel_joint">
      <hardwareInterface>hardware_interface/VelocityJointInterface</hardwareInterface>
    </joint>
    <actuator name="darko/front_left_wheel_joint_motor">
      <mechanicalReduction>1</mechanicalReduction>
    </actuator>
  </transmission>
  <gazebo reference="darko/front_left_wheel_link">
    <mu1 value="0.0"/>
    <mu2 value="0.0"/>
    <kp value="10000000.0"/>
    <kd value="1.0"/>
    <fdir1 value="1 0 0"/>
    <turnGravityOff>false</turnGravityOff>
  </gazebo>
  <joint name="darko/back_left_wheel_joint" type="continuous">
    <parent link="darko/base_link"/>
    <child link="darko/back_left_wheel_link"/>
    <origin rpy="0 0 0" xyz="-0.2225 0.2675 0.0"/>
    <axis rpy="0 0 0" xyz="0 1 0"/>
    <limit effort="100" velocity="100"/>
    <joint_properties damping="0.0" friction="0.0"/>
  </joint>
  <link name="darko/back_left_wheel_link">
    <visual>
      <origin rpy="0 0 0" xyz="0 0 0"/>
      <geometry>
        <mesh filename="package://summit_xl_description/meshes/wheels/omni_wheel_1.dae"/>
      </geometry>
      <material name="darkgrey">
        <color rgba="0.2 0.2 0.2 1"/>
      </material>
    </visual>
    <collision>
      <origin rpy="1.5707963267948966 0 0" xyz="0 0 0"/>
      <geometry>
        <!--sphere radius="${omni_wheel_radius}" /-->
        <!--
          <xacro:if value="${reflect}">
              <mesh filename="package://summit_xl_description/meshes/wheels/omni_wheel_1.dae" />
          </xacro:if>
          <xacro:unless value="${reflect}">
              <mesh filename="package://summit_xl_description/meshes/wheels/omni_wheel_2.dae" />
					</xacro:unless>
-->
        <cylinder length="0.087" radius="0.127"/>
        <!-- sphere radius="${omni_wheel_radius}"/-->
      </geometry>
    </collision>
    <inertial>
      <mass value="6.5"/>
      <origin xyz="0 0 0"/>
      <inertia ixx="0.0303095" ixy="0" ixz="0" iyy="0.05241925" iyz="0" izz="0.0303095"/>
    </inertial>
  </link>
  <!-- Transmission is important to link the joints and the controller (see summit_xl_control/config/summit_xl_control.yaml)-->
  <transmission name="darko/back_left_wheel_joint_trans">
    <type>transmission_interface/SimpleTransmission</type>
    <joint name="darko/back_left_wheel_joint">
      <hardwareInterface>hardware_interface/VelocityJointInterface</hardwareInterface>
    </joint>
    <actuator name="darko/back_left_wheel_joint_motor">
      <mechanicalReduction>1</mechanicalReduction>
    </actuator>
  </transmission>
  <gazebo reference="darko/back_left_wheel_link">
    <mu1 value="0.0"/>
    <mu2 value="0.0"/>
    <kp value="10000000.0"/>
    <kd value="1.0"/>
    <fdir1 value="1 0 0"/>
    <turnGravityOff>false</turnGravityOff>
  </gazebo>
  <joint name="darko/back_right_wheel_joint" type="continuous">
    <parent link="darko/base_link"/>
    <child link="darko/back_right_wheel_link"/>
    <origin rpy="0 0 0" xyz="-0.2225 -0.2675 0.0"/>
    <axis rpy="0 0 0" xyz="0 1 0"/>
    <limit effort="100" velocity="100"/>
    <joint_properties damping="0.0" friction="0.0"/>
  </joint>
  <link name="darko/back_right_wheel_link">
    <visual>
      <origin rpy="0 0 0" xyz="0 0 0"/>
      <geometry>
        <mesh filename="package://summit_xl_description/meshes/wheels/omni_wheel_2.dae"/>
      </geometry>
      <material name="darkgrey">
        <color rgba="0.2 0.2 0.2 1"/>
      </material>
    </visual>
    <collision>
      <origin rpy="1.5707963267948966 0 0" xyz="0 0 0"/>
      <geometry>
        <!--sphere radius="${omni_wheel_radius}" /-->
        <!--
          <xacro:if value="${reflect}">
              <mesh filename="package://summit_xl_description/meshes/wheels/omni_wheel_1.dae" />
          </xacro:if>
          <xacro:unless value="${reflect}">
              <mesh filename="package://summit_xl_description/meshes/wheels/omni_wheel_2.dae" />
					</xacro:unless>
-->
        <cylinder length="0.087" radius="0.127"/>
        <!-- sphere radius="${omni_wheel_radius}"/-->
      </geometry>
    </collision>
    <inertial>
      <mass value="6.5"/>
      <origin xyz="0 0 0"/>
      <inertia ixx="0.0303095" ixy="0" ixz="0" iyy="0.05241925" iyz="0" izz="0.0303095"/>
    </inertial>
  </link>
  <!-- Transmission is important to link the joints and the controller (see summit_xl_control/config/summit_xl_control.yaml)-->
  <transmission name="darko/back_right_wheel_joint_trans">
    <type>transmission_interface/SimpleTransmission</type>
    <joint name="darko/back_right_wheel_joint">
      <hardwareInterface>hardware_interface/VelocityJointInterface</hardwareInterface>
    </joint>
    <actuator name="darko/back_right_wheel_joint_motor">
      <mechanicalReduction>1</mechanicalReduction>
    </actuator>
  </transmission>
  <gazebo reference="darko/back_right_wheel_link">
    <mu1 value="0.0"/>
    <mu2 value="0.0"/>
    <kp value="10000000.0"/>
    <kd value="1.0"/>
    <fdir1 value="1 0 0"/>
    <turnGravityOff>false</turnGravityOff>
  </gazebo>
  <joint name="darko/imu_joint" type="fixed">
    <axis xyz="1 0 0"/>
    <!--origin xyz="0 0 0.2825"/-->
    <origin rpy="0 0 0" xyz="0.127 -0.129 0.212"/>
    <parent link="darko/base_link"/>
    <child link="darko/imu_link"/>
  </joint>
  <link name="darko/imu_link">
    <inertial>
      <origin rpy="0 0 0" xyz="0.0 0 0.01"/>
      <mass value="0.005"/>
      <inertia ixx="8.333333333333334e-10" ixy="0" ixz="0" iyy="8.333333333333334e-10" iyz="0" izz="8.333333333333334e-10"/>
    </inertial>
    <visual>
      <origin rpy="0 0 0" xyz="0 0 0"/>
      <geometry>
        <box size="0.001 0.001 0.001"/>
      </geometry>
    </visual>
    <!--collision>
	        <origin rpy="0 0 0" xyz="0 0 0"/>
	        <geometry>
	          <box size="0.001 0.001 0.001"/>
	        </geometry>
	      </collision-->
  </link>
  <!--<gazebo>-->
  <!--<plugin name="${prefix}_controller" filename="libgazebo_ros_imu.so">-->
  <!--<topicName>${ns}imu/data</topicName>-->
  <!--<serviceName>imu/service</serviceName>-->
  <!--<bodyName>${prefix}_link</bodyName>-->
  <!--<updateRateHZ>50.0</updateRateHZ>-->
  <!--<gaussianNoise>0.0</gaussianNoise>-->
  <!--</plugin>-->
  <!--</gazebo>-->
  <gazebo reference="darko/imu_link">
    <gravity>true</gravity>
    <sensor name="darko/imu_imu_sensor" type="imu">
      <always_on>true</always_on>
      <update_rate>100</update_rate>
      <visualize>true</visualize>
      <topic>__default_topic__</topic>
      <plugin filename="libgazebo_ros_imu_sensor.so" name="darko/imu_imu_plugin">
        <topicName>imu/data</topicName>
        <bodyName>darko/imu_link</bodyName>
        <updateRateHZ>100.0</updateRateHZ>
        <gaussianNoise>0.0</gaussianNoise>
        <xyzOffset>0 0 0</xyzOffset>
        <rpyOffset>0 0 0</rpyOffset>
        <frameName>darko/imu_link</frameName>
      </plugin>
      <pose>0 0 0 0 0 0</pose>
    </sensor>
  </gazebo>
  <!-- MOUNTING STRUCTURES -->
  <!-- Mounting Platform, Bottom Level (0): attach to robot's base link -->
  <joint name="darko/platform_0_joint" type="fixed">
    <origin rpy="0 0 0" xyz="0 0 0.38"/>
    <parent link="darko/base_link"/>
    <child link="darko/platform_0_link"/>
  </joint>
  <link name="darko/platform_0_link"/>
  <joint name="darko/platform_1_base_joint" type="fixed">
    <origin rpy="0 0 0" xyz="0 0 0.0"/>
    <parent link="darko/platform_0_link"/>
    <child link="darko/platform_1_link"/>
  </joint>
  <link name="darko/platform_1_link">
    <visual>
      <origin rpy="0 0 0" xyz="0 0 -0.19"/>
      <geometry>
        <mesh filename="package://darko_description/meshes/mounting_platform_02.dae"/>
      </geometry>
    </visual>
    <collision>
      <origin rpy="0 0 0" xyz="0 0 -0.19"/>
      <geometry>
        <mesh filename="package://darko_description/meshes/mounting_platform_02.dae"/>
      </geometry>
    </collision>
    <inertial>
      <origin rpy="0 0 0" xyz="0.0 0.0 -0.19"/>
      <mass value="3.5"/>
      <inertia ixx="0.14947916666666664" ixy="0" ixz="0" iyy="0.3295833333333334" iyz="0" izz="0.1932291666666667"/>
    </inertial>
  </link>
  <joint name="darko/platform_2_base_joint" type="fixed">
    <origin rpy="0 0 0" xyz="0 0 0.19"/>
    <parent link="darko/platform_1_link"/>
    <child link="darko/platform_2_link"/>
  </joint>
  <link name="darko/platform_2_link">
    <visual>
      <origin rpy="0 0 0" xyz="0 0 -0.19"/>
      <geometry>
        <mesh filename="package://darko_description/meshes/mounting_platform_02.dae"/>
      </geometry>
    </visual>
    <collision>
      <origin rpy="0 0 0" xyz="0 0 -0.19"/>
      <geometry>
        <mesh filename="package://darko_description/meshes/mounting_platform_02.dae"/>
      </geometry>
    </collision>
    <inertial>
      <origin rpy="0 0 0" xyz="0.0 0.0 -0.19"/>
      <mass value="3.5"/>
      <inertia ixx="0.14947916666666664" ixy="0" ixz="0" iyy="0.3295833333333334" iyz="0" izz="0.1932291666666667"/>
    </inertial>
  </link>
  <joint name="darko/front_laser_base_joint" type="fixed">
    <origin rpy="0 -3.141592653589793 2.356194490192345" xyz="0.2865 -0.20894 0.2373"/>
    <parent link="darko/base_link"/>
    <child link="darko/front_laser_base_link"/>
  </joint>
  <link name="darko/front_laser_base_link">
    <collision>
      <origin rpy="0 0 0" xyz="0 0 0.0"/>
      <geometry>
        <box size="0.010 0.010 0.010"/>
      </geometry>
    </collision>
    <visual>
      <origin rpy="0 0 0" xyz="0 0 0.0"/>
      <geometry>
        <mesh filename="package://robotnik_sensors/meshes/hokuyo_ust_10lx.dae"/>
      </geometry>
    </visual>
    <inertial>
      <origin rpy="0 0 0" xyz="0.0 0 0.035"/>
      <mass value="0.130"/>
      <inertia ixx="8.016666666666669e-05" ixy="0" ixz="0" iyy="8.016666666666669e-05" iyz="0" izz="5.4166666666666685e-05"/>
    </inertial>
  </link>
  <joint name="darko/front_laser_joint" type="fixed">
    <origin rpy="0 0 0" xyz="0 0 0.0474"/>
    <parent link="darko/front_laser_base_link"/>
    <child link="darko/front_laser_link"/>
  </joint>
  <link name="darko/front_laser_link">
    </link>
  <gazebo reference="darko/front_laser_link">
    <sensor name="darko/front_laser_sensor" type="ray">
      <pose>0 0 0 0 0 0</pose>
      <visualize>false</visualize>
      <update_rate>40</update_rate>
      <ray>
        <scan>
          <horizontal>
            <samples>1081</samples>
            <resolution>1</resolution>
            <min_angle>-2.3562</min_angle>
            <max_angle>2.3562</max_angle>
          </horizontal>
        </scan>
        <range>
          <min>0.06</min>
          <max>10.0</max>
          <!-- resolution>0.004363323</resolution -->
          <resolution>0.004359297</resolution>
          <!-- resolution>0.001</resolution -->
        </range>
        <noise>
          <type>gaussian</type>
          <mean>0.0</mean>
          <stddev>0.01</stddev>
        </noise>
      </ray>
      <plugin filename="libgazebo_ros_laser.so" name="darko/front_laser_controller">
        <topicName>front_laser/scan</topicName>
        <frameName>/darko/front_laser_link</frameName>
      </plugin>
    </sensor>
  </gazebo>
  <!--
        <xacro:sensor_sick_s300 prefix="$(arg prefix)rear_laser" parent="$(arg prefix)base_link" prefix_topic="rear_laser" gpu="$(arg gpu)">
            <origin xyz="${rear_laser_offset_x} ${rear_laser_offset_y} ${rear_laser_offset_z}" rpy="0 ${-PI} ${-1/4*PI}" />
        </xacro:sensor_sick_s300>
        -->
  <!--CONTAINER -->
  <joint name="darko/rear_laser_support_joint" type="fixed">
    <origin rpy="0 0 2.356194490192345" xyz="-0.2865 0.20894 0.2023"/>
    <parent link="darko/base_link"/>
    <child link="darko/rear_laser_support_link"/>
  </joint>
  <link name="darko/rear_laser_support_link">
    <visual>
      <geometry>
        <mesh filename="package://summit_xl_description/meshes/structures/sick_microscan3_support.stl"/>
      </geometry>
    </visual>
    <collision>
      <origin rpy="0 0 0" xyz="0.0 0 0"/>
      <geometry>
        <!--box size="0.12 0.1 0.1" /-->
        <mesh filename="package://summit_xl_description/meshes/structures/sick_microscan3_support.stl"/>
      </geometry>
    </collision>
  </link>
  <joint name="darko/rear_laser_base_joint" type="fixed">
    <origin rpy="3.141592653589793 0 0" xyz="0.16 0 -0.04"/>
    <parent link="darko/rear_laser_support_link"/>
    <child link="darko/rear_laser_base_link"/>
  </joint>
  <link name="darko/rear_laser_base_link">
    <collision>
      <origin rpy="0 0 0" xyz="0 0 0"/>
      <geometry>
        <!--<box size="0.106 0.094 0.152"/>-->
        <!--<cylinder radius="0.058" length="0.152"/>-->
        <mesh filename="package://robotnik_sensors/meshes/sick_microscan3.dae"/>
      </geometry>
    </collision>
    <visual>
      <origin rpy="0 0 0" xyz="0 0 0"/>
      <geometry>
        <mesh filename="package://robotnik_sensors/meshes/sick_microscan3.dae"/>
      </geometry>
    </visual>
    <inertial>
      <mass value="1.15"/>
      <origin rpy="0 0 0" xyz="0 0 0.075"/>
      <inertia ixx="0.0033370124999999996" ixy="0" ixz="0" iyy="0.003358383333333333" iyz="0" izz="0.0023828958333333332"/>
    </inertial>
  </link>
  <joint name="darko/rear_laser_joint" type="fixed">
    <parent link="darko/rear_laser_base_link"/>
    <child link="darko/rear_laser_link"/>
    <origin rpy="0 0 0" xyz="0.0 0 0.110"/>
  </joint>
  <link name="darko/rear_laser_link"/>
  <!-- Sick sensor sensor for simulation -->
  <sensor_sick_microscan3_gazebo/>
  <joint name="darko/ouster_base_joint" type="fixed">
    <origin rpy="0 0 0" xyz="0.33 -0.27 0.515"/>
    <parent link="darko/platform_2_link"/>
    <child link="darko/ouster_base_link"/>
  </joint>
  <link name="darko/ouster_base_link">
    <visual>
      <origin rpy="0 0 0" xyz="0 0 0"/>
      <geometry>
        <mesh filename="package://darko_description/meshes/ouster_os0.dae"/>
      </geometry>
      <material name="black_alu"/>
    </visual>
    <!--
      <collision>
        <origin xyz="0 0 0" rpy="0 0 0"/>
        <geometry>
          <mesh filename="package://robotnik_sensors/meshes/ouster_os0.dae"/>
        </geometry>
      </collision>
      -->
    <inertial>
      <origin rpy="0 0 0" xyz="-0.0 0.0 0.029"/>
      <mass value="1.0"/>
      <inertia ixx="0.0005803333333333333" ixy="0" ixz="0" iyy="0.0005803333333333333" iyz="0" izz="0.0006"/>
    </inertial>
  </link>
  <joint name="darko/ouster_joint" type="fixed">
    <parent link="darko/ouster_base_link"/>
    <child link="darko/ouster_link"/>
    <origin rpy="0 0 0" xyz="0.0 0 0.0365"/>
  </joint>
  <link name="darko/ouster_link"/>
  <sensor_ouster0_gazebo fps="1" gpu="False" hfov="360.0" hsamples="512" range_max="120.0" range_min="0.25" vfov="90.0" vsamples="128"/>
  <joint name="darko/lidar_tower_base_joint" type="fixed">
    <origin rpy="0 0 0" xyz="0 0 0"/>
    <parent link="darko/ouster_base_link"/>
    <child link="darko/lidar_tower_base_link"/>
  </joint>
  <link name="darko/lidar_tower_base_link">
    <visual>
      <origin rpy="0 0 0" xyz="0 0 0"/>
      <geometry>
        <mesh filename="package://darko_description/meshes/lidar_tower_50cm.dae"/>
      </geometry>
    </visual>
    <collision>
      <origin rpy="0 0 0" xyz="0 0 0"/>
      <geometry>
        <mesh filename="package://darko_description/meshes/lidar_tower_50cm_collision.dae"/>
        <!-- prevents lidar rays from being blocked by upper mounting disc -->
      </geometry>
    </collision>
    <inertial>
      <origin rpy="0 0 0" xyz="0.0 0.0 0"/>
      <mass value="1.0"/>
      <inertia ixx="0.020966666666666665" ixy="0" ixz="0" iyy="0.0002666666666666667" iyz="0" izz="0.020966666666666665"/>
    </inertial>
  </link>
  <joint name="darko/lidar_tower_joint" type="fixed">
    <parent link="darko/lidar_tower_base_link"/>
    <child link="darko/lidar_tower_link"/>
    <origin rpy="0 0 0" xyz="0 0 0"/>
  </joint>
  <link name="darko/lidar_tower_link"/>
  <!-- Base joint for visual and collision model -->
  <joint name="darko/front_basler_cam_joint" type="fixed">
    <origin rpy="0 0 0" xyz="0.03 0.035 -0.1"/>
    <parent link="darko/ouster_base_link"/>
    <child link="darko/front_basler_cam_link"/>
  </joint>
  <link name="darko/front_basler_cam_link">
    <visual>
      <origin rpy="0 0 1.5707963267948966" xyz="0 0 0"/>
      <geometry>
        <mesh filename="package://darko_description/meshes/basler_ace_with_m12_lens.dae"/>
      </geometry>
    </visual>
    <collision>
      <origin rpy="0 0 1.5707963267948966" xyz="0 0 0"/>
      <geometry>
        <mesh filename="package://darko_description/meshes/basler_ace_with_m12_lens.dae"/>
      </geometry>
    </collision>
    <inertial>
      <origin rpy="0 0 0" xyz="0 0 0"/>
      <mass value="0.1"/>
      <inertia ixx="1.5e-05" ixy="0" ixz="0" iyy="1.5e-05" iyz="0" izz="1.5e-05"/>
    </inertial>
  </link>
  <!-- RGB base link -->
  <joint name="darko/front_basler_cam_rgb_joint" type="fixed">
    <origin rpy="0 0 0" xyz="0.0 0.0 0.0"/>
    <parent link="darko/front_basler_cam_link"/>
    <child link="darko/front_basler_cam_rgb_base_link"/>
  </joint>
  <link name="darko/front_basler_cam_rgb_base_link"/>
  <!-- RGB camera to image space -->
  <joint name="darko/front_basler_cam_rgb_optical_joint" type="fixed">
    <origin rpy="-1.5707963267948966 0 -1.5707963267948966" xyz="0 0 0"/>
    <parent link="darko/front_basler_cam_rgb_base_link"/>
    <child link="darko/front_basler_cam_rgb_optical_frame"/>
  </joint>
  <link name="darko/front_basler_cam_rgb_optical_frame"/>
  <!-- Camera sensor for simulation -->
  <sensor_basler_cam_gazebo/>
  <!-- Base joint for visual and collision model -->
  <joint name="darko/rear_basler_cam_joint" type="fixed">
    <origin rpy="0 0 3.141592653589793" xyz="-0.03 -0.035 -0.1"/>
    <parent link="darko/ouster_base_link"/>
    <child link="darko/rear_basler_cam_link"/>
  </joint>
  <link name="darko/rear_basler_cam_link">
    <visual>
      <origin rpy="0 0 1.5707963267948966" xyz="0 0 0"/>
      <geometry>
        <mesh filename="package://darko_description/meshes/basler_ace_with_m12_lens.dae"/>
      </geometry>
    </visual>
    <collision>
      <origin rpy="0 0 1.5707963267948966" xyz="0 0 0"/>
      <geometry>
        <mesh filename="package://darko_description/meshes/basler_ace_with_m12_lens.dae"/>
      </geometry>
    </collision>
    <inertial>
      <origin rpy="0 0 0" xyz="0 0 0"/>
      <mass value="0.1"/>
      <inertia ixx="1.5e-05" ixy="0" ixz="0" iyy="1.5e-05" iyz="0" izz="1.5e-05"/>
    </inertial>
  </link>
  <!-- RGB base link -->
  <joint name="darko/rear_basler_cam_rgb_joint" type="fixed">
    <origin rpy="0 0 0" xyz="0.0 0.0 0.0"/>
    <parent link="darko/rear_basler_cam_link"/>
    <child link="darko/rear_basler_cam_rgb_base_link"/>
  </joint>
  <link name="darko/rear_basler_cam_rgb_base_link"/>
  <!-- RGB camera to image space -->
  <joint name="darko/rear_basler_cam_rgb_optical_joint" type="fixed">
    <origin rpy="-1.5707963267948966 0 -1.5707963267948966" xyz="0 0 0"/>
    <parent link="darko/rear_basler_cam_rgb_base_link"/>
    <child link="darko/rear_basler_cam_rgb_optical_frame"/>
  </joint>
  <link name="darko/rear_basler_cam_rgb_optical_frame"/>
  <!-- Camera sensor for simulation -->
  <sensor_basler_cam_gazebo/>
  <!-- Base joint for visual and collision model -->
  <joint name="darko/front_kinect4a_joint" type="fixed">
    <origin rpy="0 0 0" xyz="0.314 0 -0.064"/>
    <parent link="darko/platform_2_link"/>
    <child link="darko/front_kinect4a_link"/>
  </joint>
  <link name="darko/front_kinect4a_link">
    <visual>
      <origin rpy="0 0 1.5707963267948966" xyz="0 0 0"/>
      <geometry>
        <mesh filename="package://darko_description/meshes/azure_kinect.dae"/>
      </geometry>
    </visual>
    <collision>
      <origin rpy="0 0 1.5707963267948966" xyz="0 0 0"/>
      <geometry>
        <mesh filename="package://darko_description/meshes/azure_kinect.dae"/>
      </geometry>
    </collision>
    <inertial>
      <origin rpy="0 0 0" xyz="0 0 0"/>
      <mass value="0.4"/>
      <inertia ixx="0.0008033333333333334" ixy="0" ixz="0" iyy="0.0005333333333333334" iyz="0" izz="0.0012300000000000002"/>
    </inertial>
  </link>
  <!-- TODO: Not sure how well this is aligned with real-world K4A TF transforms -->
  <!-- RGB base link -->
  <joint name="darko/front_kinect4a_rgb_joint" type="fixed">
    <origin rpy="0 0 0" xyz="0.055 -0.032 0.004"/>
    <parent link="darko/front_kinect4a_link"/>
    <child link="darko/front_kinect4a_rgb_base_link"/>
  </joint>
  <link name="darko/front_kinect4a_rgb_base_link"/>
  <!-- RGB camera to image space -->
  <joint name="darko/front_kinect4a_rgb_optical_joint" type="fixed">
    <origin rpy="-1.5707963267948966 0 -1.5707963267948966" xyz="0 0 0"/>
    <parent link="darko/front_kinect4a_rgb_base_link"/>
    <child link="darko/front_kinect4a_rgb_optical_frame"/>
  </joint>
  <link name="darko/front_kinect4a_rgb_optical_frame"/>
  <!-- The fixed joints & links below are usually published by static_transformers launched by the OpenNi launch
       files. However, for Gazebo simulation we need them, so we add them here.
       (Hence, don't publish them additionally!) -->
  <joint name="darko/front_kinect4a_depth_joint" type="fixed">
    <origin rpy="0 0 0" xyz="0 0.032 0"/>
    <parent link="darko/front_kinect4a_rgb_base_link"/>
    <child link="darko/front_kinect4a_depth_link"/>
  </joint>
  <link name="darko/front_kinect4a_depth_link"/>
  <!-- Depth camera to image space -->
  <joint name="darko/front_kinect4a_depth_optical_joint" type="fixed">
    <origin rpy="-1.5707963267948966 0 -1.5707963267948966" xyz="0 0 0"/>
    <parent link="darko/front_kinect4a_depth_link"/>
    <child link="darko/front_kinect4a_depth_optical_frame"/>
  </joint>
  <link name="darko/front_kinect4a_depth_optical_frame"/>
  <!-- Kinect sensor for simulation -->
  <sensor_kinect4a_gazebo wfov="False"/>
  <joint name="darko/rgbd_tower_base_joint" type="fixed">
    <origin rpy="0 0 0" xyz="0.33 0.27 0.515"/>
    <parent link="darko/platform_2_link"/>
    <child link="darko/rgbd_tower_base_link"/>
  </joint>
  <link name="darko/rgbd_tower_base_link">
    <visual>
      <origin rpy="0 0 0" xyz="0 0 0"/>
      <geometry>
        <mesh filename="package://darko_description/meshes/lidar_tower_50cm.dae"/>
      </geometry>
    </visual>
    <collision>
      <origin rpy="0 0 0" xyz="0 0 0"/>
      <geometry>
        <mesh filename="package://darko_description/meshes/lidar_tower_50cm_collision.dae"/>
        <!-- prevents lidar rays from being blocked by upper mounting disc -->
      </geometry>
    </collision>
    <inertial>
      <origin rpy="0 0 0" xyz="0.0 0.0 0"/>
      <mass value="1.0"/>
      <inertia ixx="0.020966666666666665" ixy="0" ixz="0" iyy="0.0002666666666666667" iyz="0" izz="0.020966666666666665"/>
    </inertial>
  </link>
  <joint name="darko/rgbd_tower_joint" type="fixed">
    <parent link="darko/rgbd_tower_base_link"/>
    <child link="darko/rgbd_tower_link"/>
    <origin rpy="0 0 0" xyz="0 0 0"/>
  </joint>
  <link name="darko/rgbd_tower_link"/>
  <!-- Base joint for visual and collision model -->
  <joint name="darko/side_upper_kinect4a_joint" type="fixed">
    <origin rpy="0 0.17453292519943295 1.9547687622336491" xyz="-0.08 0 0.0"/>
    <parent link="darko/rgbd_tower_link"/>
    <child link="darko/side_upper_kinect4a_link"/>
  </joint>
  <link name="darko/side_upper_kinect4a_link">
    <visual>
      <origin rpy="0 0 1.5707963267948966" xyz="0 0 0"/>
      <geometry>
        <mesh filename="package://darko_description/meshes/azure_kinect.dae"/>
      </geometry>
    </visual>
    <collision>
      <origin rpy="0 0 1.5707963267948966" xyz="0 0 0"/>
      <geometry>
        <mesh filename="package://darko_description/meshes/azure_kinect.dae"/>
      </geometry>
    </collision>
    <inertial>
      <origin rpy="0 0 0" xyz="0 0 0"/>
      <mass value="0.4"/>
      <inertia ixx="0.0008033333333333334" ixy="0" ixz="0" iyy="0.0005333333333333334" iyz="0" izz="0.0012300000000000002"/>
    </inertial>
  </link>
  <!-- TODO: Not sure how well this is aligned with real-world K4A TF transforms -->
  <!-- RGB base link -->
  <joint name="darko/side_upper_kinect4a_rgb_joint" type="fixed">
    <origin rpy="0 0 0" xyz="0.055 -0.032 0.004"/>
    <parent link="darko/side_upper_kinect4a_link"/>
    <child link="darko/side_upper_kinect4a_rgb_base_link"/>
  </joint>
  <link name="darko/side_upper_kinect4a_rgb_base_link"/>
  <!-- RGB camera to image space -->
  <joint name="darko/side_upper_kinect4a_rgb_optical_joint" type="fixed">
    <origin rpy="-1.5707963267948966 0 -1.5707963267948966" xyz="0 0 0"/>
    <parent link="darko/side_upper_kinect4a_rgb_base_link"/>
    <child link="darko/side_upper_kinect4a_rgb_optical_frame"/>
  </joint>
  <link name="darko/side_upper_kinect4a_rgb_optical_frame"/>
  <!-- The fixed joints & links below are usually published by static_transformers launched by the OpenNi launch
       files. However, for Gazebo simulation we need them, so we add them here.
       (Hence, don't publish them additionally!) -->
  <joint name="darko/side_upper_kinect4a_depth_joint" type="fixed">
    <origin rpy="0 0 0" xyz="0 0.032 0"/>
    <parent link="darko/side_upper_kinect4a_rgb_base_link"/>
    <child link="darko/side_upper_kinect4a_depth_link"/>
  </joint>
  <link name="darko/side_upper_kinect4a_depth_link"/>
  <!-- Depth camera to image space -->
  <joint name="darko/side_upper_kinect4a_depth_optical_joint" type="fixed">
    <origin rpy="-1.5707963267948966 0 -1.5707963267948966" xyz="0 0 0"/>
    <parent link="darko/side_upper_kinect4a_depth_link"/>
    <child link="darko/side_upper_kinect4a_depth_optical_frame"/>
  </joint>
  <link name="darko/side_upper_kinect4a_depth_optical_frame"/>
  <!-- Kinect sensor for simulation -->
  <sensor_kinect4a_gazebo wfov="True"/>
  <!-- Base joint for visual and collision model -->
  <joint name="darko/side_lower_kinect4a_joint" type="fixed">
    <origin rpy="0 0.5235987755982988 1.9547687622336491" xyz="-0.08 0 -0.3"/>
    <parent link="darko/rgbd_tower_link"/>
    <child link="darko/side_lower_kinect4a_link"/>
  </joint>
  <link name="darko/side_lower_kinect4a_link">
    <visual>
      <origin rpy="0 0 1.5707963267948966" xyz="0 0 0"/>
      <geometry>
        <mesh filename="package://darko_description/meshes/azure_kinect.dae"/>
      </geometry>
    </visual>
    <collision>
      <origin rpy="0 0 1.5707963267948966" xyz="0 0 0"/>
      <geometry>
        <mesh filename="package://darko_description/meshes/azure_kinect.dae"/>
      </geometry>
    </collision>
    <inertial>
      <origin rpy="0 0 0" xyz="0 0 0"/>
      <mass value="0.4"/>
      <inertia ixx="0.0008033333333333334" ixy="0" ixz="0" iyy="0.0005333333333333334" iyz="0" izz="0.0012300000000000002"/>
    </inertial>
  </link>
  <!-- TODO: Not sure how well this is aligned with real-world K4A TF transforms -->
  <!-- RGB base link -->
  <joint name="darko/side_lower_kinect4a_rgb_joint" type="fixed">
    <origin rpy="0 0 0" xyz="0.055 -0.032 0.004"/>
    <parent link="darko/side_lower_kinect4a_link"/>
    <child link="darko/side_lower_kinect4a_rgb_base_link"/>
  </joint>
  <link name="darko/side_lower_kinect4a_rgb_base_link"/>
  <!-- RGB camera to image space -->
  <joint name="darko/side_lower_kinect4a_rgb_optical_joint" type="fixed">
    <origin rpy="-1.5707963267948966 0 -1.5707963267948966" xyz="0 0 0"/>
    <parent link="darko/side_lower_kinect4a_rgb_base_link"/>
    <child link="darko/side_lower_kinect4a_rgb_optical_frame"/>
  </joint>
  <link name="darko/side_lower_kinect4a_rgb_optical_frame"/>
  <!-- The fixed joints & links below are usually published by static_transformers launched by the OpenNi launch
       files. However, for Gazebo simulation we need them, so we add them here.
       (Hence, don't publish them additionally!) -->
  <joint name="darko/side_lower_kinect4a_depth_joint" type="fixed">
    <origin rpy="0 0 0" xyz="0 0.032 0"/>
    <parent link="darko/side_lower_kinect4a_rgb_base_link"/>
    <child link="darko/side_lower_kinect4a_depth_link"/>
  </joint>
  <link name="darko/side_lower_kinect4a_depth_link"/>
  <!-- Depth camera to image space -->
  <joint name="darko/side_lower_kinect4a_depth_optical_joint" type="fixed">
    <origin rpy="-1.5707963267948966 0 -1.5707963267948966" xyz="0 0 0"/>
    <parent link="darko/side_lower_kinect4a_depth_link"/>
    <child link="darko/side_lower_kinect4a_depth_optical_frame"/>
  </joint>
  <link name="darko/side_lower_kinect4a_depth_optical_frame"/>
  <!-- Kinect sensor for simulation -->
  <sensor_kinect4a_gazebo wfov="True"/>
  <!-- TODO: The following lines were included in the original Robotnik config, and are probably obsolete. -->
  <!--xacro:sensor_axis_m5013 prefix="$(arg prefix)front_ptz_camera" parent="$(arg prefix)base_link">
            <origin xyz="${front_ptz_camera_offset_x} ${front_ptz_camera_offset_y} ${front_ptz_camera_offset_z}" rpy="${-PI/2} 0 0"/>
        </xacro:sensor_axis_m5013-->
  <!--xacro:sensor_axis_m5013 prefix="$(arg prefix)rear_ptz_camera" parent="$(arg prefix)base_link">
            <origin xyz="${rear_ptz_camera_offset_x} ${rear_ptz_camera_offset_y} ${rear_ptz_camera_offset_z}" rpy="${-PI/2} 0 ${PI}"/>
        </xacro:sensor_axis_m5013-->
  <!--xacro:sensor_orbbec_astra prefix="$(arg prefix)front_rgbd_camera" parent="$(arg prefix)base_link" prefix_topic="front_rgbd_camera">
            <origin xyz="${front_rgbd_camera_offset_x} ${front_rgbd_camera_offset_y} ${front_rgbd_camera_offset_z}" rpy="0 0 0"/>
        </xacro:sensor_orbbec_astra-->
  <!-- ARM AND CONTROLLER -->
  <joint name="darko/panda_controller_base_joint" type="fixed">
    <origin rpy="0 0 0" xyz="0 0 0.0"/>
    <parent link="darko/platform_0_link"/>
    <child link="darko/panda_controller_base_link"/>
  </joint>
  <link name="darko/panda_controller_base_link">
    <visual>
      <origin rpy="0 0 0" xyz="0 0 0"/>
      <geometry>
        <mesh filename="package://darko_description/meshes/panda_controller.dae"/>
      </geometry>
    </visual>
    <collision>
      <origin rpy="0 0 0" xyz="0 0 0"/>
      <geometry>
        <mesh filename="package://darko_description/meshes/panda_controller.dae"/>
      </geometry>
    </collision>
    <inertial>
      <origin rpy="0 0 0" xyz="0.0 0.0 0"/>
      <mass value="8.0"/>
      <inertia ixx="0.08706666666666667" ixy="0" ixz="0" iyy="0.24833333333333332" iyz="0" izz="0.17206666666666667"/>
    </inertial>
  </link>
  <joint name="darko/panda_controller_joint" type="fixed">
    <parent link="darko/panda_controller_base_link"/>
    <child link="darko/panda_controller_link"/>
    <origin rpy="0 0 0" xyz="0 0 0"/>
  </joint>
  <link name="darko/panda_controller_link"/>
  <!-- Add Franka arm from panda_simulation -->
  <joint name="darko/panda_mount_joint" type="fixed">
    <origin rpy="0 0 3.141592653589793" xyz="-0.23 0 0.0"/>
    <parent link="darko/platform_2_link"/>
    <child link="darko/panda_mount_link"/>
  </joint>
  <link name="darko/panda_mount_link"/>
  <!-- If using a different frame with ${connected_to} param, make sure 'world' frame exists in the TF tree -->
  <joint name="darko/hand_joint" type="fixed">
    <origin rpy="0 0 0" xyz="0 0 0"/>
    <parent link="panda_link8"/>
    <child link="darko/hand_base_link"/>
  </joint>
  <link name="darko/hand_base_link">
    <inertial>
      <origin rpy="0 0 0" xyz="-0.000222201146896917 2.99284922239407E-06 0.0365598116000577"/>
      <mass value="0.359681668644718"/>
      <inertia ixx="0.000426094138511423" ixy="-3.47685971240899E-10" ixz="-3.70902449457946E-07" iyy="0.000421830861136388" iyz="-1.73791620761484E-10" izz="0.000552700185384758"/>
    </inertial>
    <visual>
      <origin rpy="0 0 0" xyz="0 0 0"/>
      <geometry>
        <mesh filename="package://dh3_urdf/meshes/base_Link.STL"/>
      </geometry>
      <material name="">
        <color rgba="1 1 1 1"/>
      </material>
    </visual>
    <collision>
      <origin rpy="0 0 0" xyz="0 0 0"/>
      <geometry>
        <mesh filename="package://dh3_urdf/meshes/base_Link.STL"/>
      </geometry>
    </collision>
  </link>
  <link name="darko/hand_finger1_base_link">
    <inertial>
      <origin rpy="0 0 0" xyz="-0.000601794667080963 -0.00110288755052515 0.00521005597269414"/>
      <mass value="0.00832299911583519"/>
      <inertia ixx="9.16214830766921E-07" ixy="2.57171997873981E-08" ixz="1.43130193804266E-08" iyy="1.14280462688504E-06" iyz="5.78075867067328E-08" izz="1.77055158585085E-06"/>
    </inertial>
    <visual>
      <origin rpy="0 0 0" xyz="0 0 0"/>
      <geometry>
        <mesh filename="package://dh3_urdf/meshes/finger1_base_Link.STL"/>
      </geometry>
      <material name="">
        <color rgba="1 1 1 1"/>
      </material>
    </visual>
    <collision>
      <origin rpy="0 0 0" xyz="0 0 0"/>
      <geometry>
        <mesh filename="package://dh3_urdf/meshes/finger1_base_Link.STL"/>
      </geometry>
    </collision>
  </link>
  <joint name="darko/hand_finger1_base_joint" type="revolute">
    <origin rpy="0 0 0.523598783277495" xyz="-0.0161724988655456 0.0279961367597022 0.105"/>
    <parent link="darko/hand_base_link"/>
    <child link="darko/hand_finger1_base_link"/>
    <axis xyz="0 0 -1"/>
    <limit effort="100" lower="-1" upper="0.54" velocity="100"/>
  </joint>
  <link name="darko/hand_finger1_link">
    <inertial>
      <origin rpy="0 0 0" xyz="0.0210050434938139 0.012249999999974 0.0178290357798672"/>
      <mass value="0.00557906977988049"/>
      <inertia ixx="8.99405333082292E-07" ixy="9.82637628153793E-19" ixz="-5.95537945974777E-07" iyy="1.3061675562027E-06" iyz="6.37604051045675E-19" izz="1.24905466077277E-06"/>
    </inertial>
    <visual>
      <origin rpy="0 0 0" xyz="0 0 0"/>
      <geometry>
        <mesh filename="package://dh3_urdf/meshes/finger1_Link.STL"/>
      </geometry>
      <material name="">
        <color rgba="0.0549019607843137 0.0549019607843137 0.0549019607843137 1"/>
      </material>
    </visual>
    <collision>
      <origin rpy="0 0 0" xyz="0 0 0"/>
      <geometry>
        <mesh filename="package://dh3_urdf/meshes/finger1_Link.STL"/>
      </geometry>
    </collision>
  </link>
  <joint name="darko/hand_finger1_joint" type="revolute">
    <origin rpy="0 0 1.5708" xyz="0.01225 -0.0081568 0.0175"/>
    <parent link="darko/hand_finger1_base_link"/>
    <child link="darko/hand_finger1_link"/>
    <axis xyz="0 -1 0"/>
    <limit effort="100" lower="0" upper="1.16" velocity="100"/>
  </joint>
  <link name="darko/hand_finger1_tip_link">
    <inertial>
      <origin rpy="0 0 0" xyz="0.000977109926666546 0.0123819370127123 0.0136590907193947"/>
      <mass value="0.0107564294883422"/>
      <inertia ixx="1.48949781713587E-06" ixy="-7.10872889918193E-09" ixz="1.38025837549055E-07" iyy="1.35009809053808E-06" iyz="1.24264254163864E-08" izz="4.77788297009959E-07"/>
    </inertial>
    <visual>
      <origin rpy="0 0 0" xyz="0 0 0"/>
      <geometry>
        <mesh filename="package://dh3_urdf/meshes/finger1_tip_Link.STL"/>
      </geometry>
      <material name="">
        <color rgba="1 1 1 1"/>
      </material>
    </visual>
    <collision>
      <origin rpy="0 0 0" xyz="0 0 0"/>
      <geometry>
        <mesh filename="package://dh3_urdf/meshes/finger1_tip_Link.STL"/>
      </geometry>
    </collision>
  </link>
  <joint name="darko/hand_finger1_tip_joint" type="revolute">
    <origin rpy="0 0 0" xyz="0.044029 0 0.032962"/>
    <parent link="darko/hand_finger1_link"/>
    <child link="darko/hand_finger1_tip_link"/>
    <axis xyz="0 -1 0"/>
    <limit effort="100" lower="-1" upper="1" velocity="100"/>
    <mimic joint="darko/hand_finger1_joint" multiplier="-1" offset="0"/>
  </joint>
  <link name="darko/hand_finger1_outlet_link">
    <inertial>
      <origin rpy="0 0 0" xyz="0.0205745260056277 -0.00269403354044023 0.0154029170399833"/>
      <mass value="0.00494212097275844"/>
      <inertia ixx="3.17521820164163E-07" ixy="-1.11658813824013E-10" ixz="-3.22040978315679E-07" iyy="7.52126023069253E-07" iyz="-8.36396169396533E-11" izz="5.06597025546867E-07"/>
    </inertial>
    <visual>
      <origin rpy="0 0 0" xyz="0 0 0"/>
      <geometry>
        <mesh filename="package://dh3_urdf/meshes/finger1_outlet_Link.STL"/>
      </geometry>
      <material name="">
        <color rgba="1 1 1 1"/>
      </material>
    </visual>
    <collision>
      <origin rpy="0 0 0" xyz="0 0 0"/>
      <geometry>
        <mesh filename="package://dh3_urdf/meshes/finger1_outlet_Link.STL"/>
      </geometry>
    </collision>
  </link>
  <joint name="darko/hand_finger1_outlet_joint" type="revolute">
    <origin rpy="0 0 1.5708" xyz="-0.01035 0.0081568 0.0098929"/>
    <parent link="darko/hand_finger1_base_link"/>
    <child link="darko/hand_finger1_outlet_link"/>
    <axis xyz="0 1 0"/>
    <limit effort="0" lower="0" upper="0" velocity="0"/>
    <mimic joint="darko/hand_finger1_joint" multiplier="-1" offset="0"/>
  </joint>
  <link name="darko/hand_finger2_base_link">
    <inertial>
      <origin rpy="0 0 0" xyz="-0.000601794667086514 -0.00110288755052199 0.00521005597269419"/>
      <mass value="0.00832299911583519"/>
      <inertia ixx="9.16214830767147E-07" ixy="2.57171997885585E-08" ixz="1.43130193807236E-08" iyy="1.14280462688473E-06" iyz="5.78075867066608E-08" izz="1.77055158585084E-06"/>
    </inertial>
    <visual>
      <origin rpy="0 0 0" xyz="0 0 0"/>
      <geometry>
        <mesh filename="package://dh3_urdf/meshes/finger2_base_Link.STL"/>
      </geometry>
      <material name="">
        <color rgba="1 1 1 1"/>
      </material>
    </visual>
    <collision>
      <origin rpy="0 0 0" xyz="0 0 0"/>
      <geometry>
        <mesh filename="package://dh3_urdf/meshes/finger2_base_Link.STL"/>
      </geometry>
    </collision>
  </link>
  <joint name="darko/hand_finger2_base_joint" type="fixed">
    <origin rpy="0 0 -1.5708" xyz="0.032325 0 0.105"/>
    <parent link="darko/hand_base_link"/>
    <child link="darko/hand_finger2_base_link"/>
    <axis xyz="0 0 0"/>
  </joint>
  <link name="darko/hand_finger2_link">
    <inertial>
      <origin rpy="0 0 0" xyz="0.021005043493832 0.0122499999999494 0.0178290357798643"/>
      <mass value="0.00557906977988033"/>
      <inertia ixx="8.99405333082248E-07" ixy="1.40895930945985E-18" ixz="-5.95537945974751E-07" iyy="1.30616755620265E-06" iyz="1.47278790722963E-18" izz="1.24905466077276E-06"/>
    </inertial>
    <visual>
      <origin rpy="0 0 0" xyz="0 0 0"/>
      <geometry>
        <mesh filename="package://dh3_urdf/meshes/finger2_link.STL"/>
      </geometry>
      <material name="">
        <color rgba="0.0549019607843137 0.0549019607843137 0.0549019607843137 1"/>
      </material>
    </visual>
    <collision>
      <origin rpy="0 0 0" xyz="0 0 0"/>
      <geometry>
        <mesh filename="package://dh3_urdf/meshes/finger2_link.STL"/>
      </geometry>
    </collision>
  </link>
  <joint name="darko/hand_finger2_joint" type="revolute">
    <origin rpy="0 0 1.5708" xyz="0.01225 -0.0081568 0.0175"/>
    <parent link="darko/hand_finger2_base_link"/>
    <child link="darko/hand_finger2_link"/>
    <axis xyz="0 -1 0"/>
    <limit effort="0" lower="0" upper="0" velocity="0"/>
    <mimic joint="darko/hand_finger1_joint" multiplier="1" offset="0"/>
  </joint>
  <link name="darko/hand_finger2_tip_link">
    <inertial>
      <origin rpy="0 0 0" xyz="0.000977109970519835 0.0123819365363909 0.0136590906877767"/>
      <mass value="0.0107564295938579"/>
      <inertia ixx="1.48949781977635E-06" ixy="-7.10872109767472E-09" ixz="1.38025837268698E-07" iyy="1.35009809568266E-06" iyz="1.24264681742315E-08" izz="4.77788294510709E-07"/>
    </inertial>
    <visual>
      <origin rpy="0 0 0" xyz="0 0 0"/>
      <geometry>
        <mesh filename="package://dh3_urdf/meshes/finger2_tip_Link.STL"/>
      </geometry>
      <material name="">
        <color rgba="1 1 1 1"/>
      </material>
    </visual>
    <collision>
      <origin rpy="0 0 0" xyz="0 0 0"/>
      <geometry>
        <mesh filename="package://dh3_urdf/meshes/finger2_tip_Link.STL"/>
      </geometry>
    </collision>
  </link>
  <joint name="darko/hand_finger2_tip_joint" type="revolute">
    <origin rpy="0 0 0" xyz="0.044029 0 0.032962"/>
    <parent link="darko/hand_finger2_link"/>
    <child link="darko/hand_finger2_tip_link"/>
    <axis xyz="0 -1 0"/>
    <limit effort="0" lower="0" upper="0" velocity="0"/>
    <mimic joint="darko/hand_finger1_tip_joint" multiplier="1" offset="0"/>
  </joint>
  <link name="darko/hand_finger2_outlet_link">
    <inertial>
      <origin rpy="0 0 0" xyz="0.0205745216753029 -0.00269403287328564 0.0154029129942138"/>
      <mass value="0.00494212190694487"/>
      <inertia ixx="3.17522151991331E-07" ixy="-1.11440245000629E-10" ixz="-3.22041349248125E-07" iyy="7.52126778397778E-07" iyz="-8.34843588255468E-11" izz="5.06597462640552E-07"/>
    </inertial>
    <visual>
      <origin rpy="0 0 0" xyz="0 0 0"/>
      <geometry>
        <mesh filename="package://dh3_urdf/meshes/finger2_outlet_Link.STL"/>
      </geometry>
      <material name="">
        <color rgba="1 1 1 1"/>
      </material>
    </visual>
    <collision>
      <origin rpy="0 0 0" xyz="0 0 0"/>
      <geometry>
        <mesh filename="package://dh3_urdf/meshes/finger2_outlet_Link.STL"/>
      </geometry>
    </collision>
  </link>
  <joint name="darko/hand_finger2_outlet_joint" type="revolute">
    <origin rpy="0 0 1.5708" xyz="-0.01035 0.0081568 0.0098929"/>
    <parent link="darko/hand_finger2_base_link"/>
    <child link="darko/hand_finger2_outlet_link"/>
    <axis xyz="0 1 0"/>
    <limit effort="0" lower="0" upper="0" velocity="0"/>
    <mimic joint="darko/hand_finger1_outlet_joint" multiplier="1" offset="0"/>
  </joint>
  <link name="darko/hand_finger3_base_link">
    <inertial>
      <origin rpy="0 0 0" xyz="-0.000601794667079381 -0.00110288755052597 0.00521005597269403"/>
      <mass value="0.00832299911583507"/>
      <inertia ixx="9.16214830766856E-07" ixy="2.57171997871098E-08" ixz="1.43130193803543E-08" iyy="1.1428046268851E-06" iyz="5.78075867067519E-08" izz="1.77055158585085E-06"/>
    </inertial>
    <visual>
      <origin rpy="0 0 0" xyz="0 0 0"/>
      <geometry>
        <mesh filename="package://dh3_urdf/meshes/finger3_base_Link.STL"/>
      </geometry>
      <material name="">
        <color rgba="1 1 1 1"/>
      </material>
    </visual>
    <collision>
      <origin rpy="0 0 0" xyz="0 0 0"/>
      <geometry>
        <mesh filename="package://dh3_urdf/meshes/finger3_base_Link.STL"/>
      </geometry>
    </collision>
  </link>
  <joint name="darko/hand_finger3_base_joint" type="revolute">
    <origin rpy="0 0 2.618" xyz="-0.016172 -0.028004 0.105"/>
    <parent link="darko/hand_base_link"/>
    <child link="darko/hand_finger3_base_link"/>
    <axis xyz="0 0 -1"/>
    <limit effort="0" lower="0" upper="0" velocity="0"/>
    <mimic joint="darko/hand_finger1_base_joint" multiplier="-1" offset="0"/>
  </joint>
  <link name="darko/hand_finger3_link">
    <inertial>
      <origin rpy="0 0 0" xyz="0.0210050434938141 0.012249999999974 0.0178290357798672"/>
      <mass value="0.0055790697798808"/>
      <inertia ixx="8.99405333082359E-07" ixy="9.61461081223117E-19" ixz="-5.95537945974827E-07" iyy="1.30616755620281E-06" iyz="6.24087927058166E-19" izz="1.24905466077285E-06"/>
    </inertial>
    <visual>
      <origin rpy="0 0 0" xyz="0 0 0"/>
      <geometry>
        <mesh filename="package://dh3_urdf/meshes/finger3_Link.STL"/>
      </geometry>
      <material name="">
        <color rgba="0.0549019607843137 0.0549019607843137 0.0549019607843137 1"/>
      </material>
    </visual>
    <collision>
      <origin rpy="0 0 0" xyz="0 0 0"/>
      <geometry>
        <mesh filename="package://dh3_urdf/meshes/finger3_Link.STL"/>
      </geometry>
    </collision>
  </link>
  <joint name="darko/hand_finger3_joint" type="revolute">
    <origin rpy="0 0 1.5707963267949" xyz="0.0122500000000007 -0.00815677008333035 0.0174999999999995"/>
    <parent link="darko/hand_finger3_base_link"/>
    <child link="darko/hand_finger3_link"/>
    <axis xyz="0 -1 0"/>
    <limit effort="0" lower="0" upper="0" velocity="0"/>
    <mimic joint="darko/hand_finger1_joint" multiplier="1" offset="0"/>
  </joint>
  <link name="darko/hand_finger3_tip_link">
    <inertial>
      <origin rpy="0 0 0" xyz="0.000977114977738613 0.0123819369789457 0.01365909502715"/>
      <mass value="0.0107564399961694"/>
      <inertia ixx="1.48949935780095E-06" ixy="-7.10872801793197E-09" ixz="1.38025629536651E-07" iyy="1.35009963358183E-06" iyz="1.2426443300764E-08" izz="4.77788392346636E-07"/>
    </inertial>
    <visual>
      <origin rpy="0 0 0" xyz="0 0 0"/>
      <geometry>
        <mesh filename="package://dh3_urdf/meshes/finger3_tip_Link.STL"/>
      </geometry>
      <material name="">
        <color rgba="1 1 1 1"/>
      </material>
    </visual>
    <collision>
      <origin rpy="0 0 0" xyz="0 0 0"/>
      <geometry>
        <mesh filename="package://dh3_urdf/meshes/finger3_tip_Link.STL"/>
      </geometry>
    </collision>
  </link>
  <joint name="darko/hand_finger3_tip_joint" type="revolute">
    <origin rpy="0 0 0" xyz="0.044029 0 0.032962"/>
    <parent link="darko/hand_finger3_link"/>
    <child link="darko/hand_finger3_tip_link"/>
    <axis xyz="0 -1 0"/>
    <limit effort="0" lower="0" upper="0" velocity="0"/>
    <mimic joint="darko/hand_finger1_tip_joint" multiplier="1" offset="0"/>
  </joint>
  <link name="darko/hand_finger3_outlet_link">
    <inertial>
      <origin rpy="0 0 0" xyz="0.0205745375238259 -0.00269403304520632 0.0154029215009596"/>
      <mass value="0.00494212514535466"/>
      <inertia ixx="3.17522114051902E-07" ixy="-1.11543432026918E-10" ixz="-3.22041207812167E-07" iyy="7.52126509554002E-07" iyz="-8.35643256488424E-11" izz="5.0659720155034E-07"/>
    </inertial>
    <visual>
      <origin rpy="0 0 0" xyz="0 0 0"/>
      <geometry>
        <mesh filename="package://dh3_urdf/meshes/finger3_outlet_Link.STL"/>
      </geometry>
      <material name="">
        <color rgba="1 1 1 1"/>
      </material>
    </visual>
    <collision>
      <origin rpy="0 0 0" xyz="0 0 0"/>
      <geometry>
        <mesh filename="package://dh3_urdf/meshes/finger3_outlet_Link.STL"/>
      </geometry>
    </collision>
  </link>
  <joint name="darko/hand_finger3_outlet_joint" type="revolute">
    <origin rpy="0 0 1.5708" xyz="-0.01035 0.0081568 0.0098929"/>
    <parent link="darko/hand_finger3_base_link"/>
    <child link="darko/hand_finger3_outlet_link"/>
    <axis xyz="0 1 0"/>
    <limit effort="0" lower="0" upper="0" velocity="0"/>
    <mimic joint="darko/hand_finger1_outlet_joint" multiplier="1" offset="0"/>
  </joint>
  <joint name="panda_to_darko/panda_mount_link" type="fixed">
    <parent link="darko/panda_mount_link"/>
    <child link="panda_link0"/>
    <origin rpy="0 0 0" xyz="0 0 0"/>
    <dynamics damping="1.0"/>
  </joint>
  <link name="panda_link0">
    <visual>
      <geometry>
        <mesh filename="package://franka_panda_description/meshes/visual/link0.dae"/>
      </geometry>
    </visual>
    <collision>
      <geometry>
        <mesh filename="package://franka_panda_description/meshes/collision/link0.stl"/>
      </geometry>
    </collision>
    <inertial>
      <origin rpy="0 0 0" xyz="-0.025566 -2.88e-05 0.057332"/>
      <mass value="2.92"/>
      <inertia ixx="0.00782229414331" ixy="-1.56191622996e-05" ixz="-0.00126005738123" iyy="0.0109027971813" iyz="1.08233858202e-05" izz="0.0102355503949"/>
    </inertial>
  </link>
  <link name="panda_link1">
    <visual>
      <geometry>
        <mesh filename="package://franka_panda_description/meshes/visual/link1.dae"/>
      </geometry>
    </visual>
    <collision>
      <geometry>
        <mesh filename="package://franka_panda_description/meshes/collision/link1.stl"/>
      </geometry>
    </collision>
    <inertial>
      <origin rpy="0 0 0" xyz="0 -0.0324958 -0.0675818"/>
      <mass value="2.74"/>
      <inertia ixx="0.0180416958283" ixy="0" ixz="0" iyy="0.0159136071891" iyz="0.0046758424612" izz="0.00620690827127"/>
    </inertial>
  </link>
  <joint name="panda_joint1" type="revolute">
    <safety_controller k_position="100.0" k_velocity="40.0" soft_lower_limit="-2.8973" soft_upper_limit="2.8973"/>
    <origin rpy="0 0 0" xyz="0 0 0.333"/>
    <parent link="panda_link0"/>
    <child link="panda_link1"/>
    <axis xyz="0 0 1"/>
    <limit effort="87" lower="-2.8973" upper="2.8973" velocity="2.1750"/>
    <dynamics damping="10.0" friction="5.0"/>
  </joint>
  <link name="panda_link2">
    <visual>
      <geometry>
        <mesh filename="package://franka_panda_description/meshes/visual/link2.dae"/>
      </geometry>
    </visual>
    <collision>
      <geometry>
        <mesh filename="package://franka_panda_description/meshes/collision/link2.stl"/>
      </geometry>
    </collision>
    <inertial>
      <origin rpy="0 0 0" xyz="0 -0.06861 0.0322285"/>
      <mass value="2.74"/>
      <inertia ixx="0.0182856182281" ixy="0" ixz="0" iyy="0.00621358421175" iyz="-0.00472844221905" izz="0.0161514346309"/>
    </inertial>
  </link>
  <joint name="panda_joint2" type="revolute">
    <safety_controller k_position="100.0" k_velocity="40.0" soft_lower_limit="-1.7628" soft_upper_limit="1.7628"/>
    <origin rpy="-1.5707963267948966 0 0" xyz="0 0 0"/>
    <parent link="panda_link1"/>
    <child link="panda_link2"/>
    <axis xyz="0 0 1"/>
    <limit effort="87" lower="-1.7628" upper="1.7628" velocity="2.1750"/>
    <dynamics damping="5.0" friction="2.0"/>
  </joint>
  <link name="panda_link3">
    <visual>
      <geometry>
        <mesh filename="package://franka_panda_description/meshes/visual/link3.dae"/>
      </geometry>
    </visual>
    <collision>
      <geometry>
        <mesh filename="package://franka_panda_description/meshes/collision/link3.stl"/>
      </geometry>
    </collision>
    <inertial>
      <origin rpy="0 0 0" xyz="0.0469893 0.0316374 -0.031704"/>
      <mass value="2.38"/>
      <inertia ixx="0.00771376630908" ixy="-0.00248490625138" ixz="-0.00332147581033" iyy="0.00989108008727" iyz="-0.00217796151484" izz="0.00811723558464"/>
    </inertial>
  </link>
  <joint name="panda_joint3" type="revolute">
    <safety_controller k_position="100.0" k_velocity="40.0" soft_lower_limit="-2.8973" soft_upper_limit="2.8973"/>
    <origin rpy="1.5707963267948966 0 0" xyz="0 -0.316 0"/>
    <parent link="panda_link2"/>
    <child link="panda_link3"/>
    <axis xyz="0 0 1"/>
    <limit effort="87" lower="-2.8973" upper="2.8973" velocity="2.1750"/>
    <dynamics damping="5.0" friction="2.0"/>
  </joint>
  <link name="panda_link4">
    <visual>
      <geometry>
        <mesh filename="package://franka_panda_description/meshes/visual/link4.dae"/>
      </geometry>
    </visual>
    <collision>
      <geometry>
        <mesh filename="package://franka_panda_description/meshes/collision/link4.stl"/>
      </geometry>
    </collision>
    <inertial>
      <origin rpy="0 0 0" xyz="-0.0360446 0.0336853 0.031882"/>
      <mass value="2.38"/>
      <inertia ixx="0.00799663881132" ixy="0.00347095570217" ixz="-0.00241222942995" iyy="0.00825390705278" iyz="0.00235774044121" izz="0.0102515004345"/>
    </inertial>
  </link>
  <joint name="panda_joint4" type="revolute">
    <safety_controller k_position="100.0" k_velocity="40.0" soft_lower_limit="-3.0718" soft_upper_limit="-0.0698"/>
    <origin rpy="1.5707963267948966 0 0" xyz="0.0825 0 0"/>
    <parent link="panda_link3"/>
    <child link="panda_link4"/>
    <axis xyz="0 0 1"/>
    <limit effort="87" lower="-3.0718" upper="-0.0698" velocity="2.1750"/>
    <dynamics damping="1.0" friction="0.5"/>
  </joint>
  <link name="panda_link5">
    <visual>
      <geometry>
        <mesh filename="package://franka_panda_description/meshes/visual/link5.dae"/>
      </geometry>
    </visual>
    <collision>
      <geometry>
        <mesh filename="package://franka_panda_description/meshes/collision/link5.stl"/>
      </geometry>
    </collision>
    <inertial>
      <origin rpy="0 0 0" xyz="0 0.0610427 -0.104176"/>
      <mass value="2.74"/>
      <inertia ixx="0.030371374513" ixy="6.50283587108e-07" ixz="-1.05129179916e-05" iyy="0.0288752887402" iyz="-0.00775653445787" izz="0.00444134056164"/>
    </inertial>
  </link>
  <joint name="panda_joint5" type="revolute">
    <safety_controller k_position="100.0" k_velocity="40.0" soft_lower_limit="-2.8973" soft_upper_limit="2.8973"/>
    <origin rpy="-1.5707963267948966 0 0" xyz="-0.0825 0.384 0"/>
    <parent link="panda_link4"/>
    <child link="panda_link5"/>
    <axis xyz="0 0 1"/>
    <limit effort="12" lower="-2.8973" upper="2.8973" velocity="2.6100"/>
    <dynamics damping="2.0" friction="1.0"/>
  </joint>
  <link name="panda_link6">
    <visual>
      <geometry>
        <mesh filename="package://franka_panda_description/meshes/visual/link6.dae"/>
      </geometry>
    </visual>
    <collision>
      <geometry>
        <mesh filename="package://franka_panda_description/meshes/collision/link6.stl"/>
      </geometry>
    </collision>
    <inertial>
      <origin rpy="0 0 0" xyz="0.0510509 0.009108 0.0106343"/>
      <mass value="1.55"/>
      <inertia ixx="0.00303336450376" ixy="-0.000437276865508" ixz="0.000629257294877" iyy="0.00404479911567" iyz="0.000130472021025" izz="0.00558234286039"/>
    </inertial>
  </link>
  <joint name="panda_joint6" type="revolute">
    <safety_controller k_position="100.0" k_velocity="40.0" soft_lower_limit="-0.0175" soft_upper_limit="3.7525"/>
    <origin rpy="1.5707963267948966 0 0" xyz="0 0 0"/>
    <parent link="panda_link5"/>
    <child link="panda_link6"/>
    <axis xyz="0 0 1"/>
    <limit effort="12" lower="-0.0175" upper="3.7525" velocity="2.6100"/>
    <dynamics damping="1.0" friction="0.5"/>
  </joint>
  <link name="panda_link7">
    <visual>
      <geometry>
        <mesh filename="package://franka_panda_description/meshes/visual/link7.dae"/>
      </geometry>
    </visual>
    <collision>
      <geometry>
        <mesh filename="package://franka_panda_description/meshes/collision/link7.stl"/>
      </geometry>
    </collision>
    <inertial>
      <origin rpy="0 0 0" xyz="0.0109695 0.0107965 0.0650411"/>
      <mass value="0.54"/>
      <inertia ixx="0.000888868887021" ixy="-0.00012239074652" ixz="3.98699829666e-05" iyy="0.000888001373233" iyz="-9.33825115206e-05" izz="0.0007176834609"/>
    </inertial>
  </link>
  <joint name="panda_joint7" type="revolute">
    <safety_controller k_position="100.0" k_velocity="40.0" soft_lower_limit="-2.8973" soft_upper_limit="2.8973"/>
    <origin rpy="1.5707963267948966 0 0" xyz="0.088 0 0"/>
    <parent link="panda_link6"/>
    <child link="panda_link7"/>
    <axis xyz="0 0 1"/>
    <limit effort="12" lower="-2.8973" upper="2.8973" velocity="2.6100"/>
    <dynamics damping="1.0" friction="0.5"/>
  </joint>
  <link name="panda_link8">
    <inertial>
      <origin rpy="0 0 0" xyz="0 0 0"/>
      <mass value="0.0"/>
      <inertia ixx="0.0" ixy="0.0" ixz="0.0" iyy="0.0" iyz="0.0" izz="0.0"/>
    </inertial>
  </link>
  <joint name="panda_joint8" type="fixed">
    <origin rpy="0 0 0" xyz="0 0 0.107"/>
    <parent link="panda_link7"/>
    <child link="panda_link8"/>
    <axis xyz="0 0 0"/>
  </joint>
  <gazebo reference="panda_joint7">
    <implicitSpringDamper>1</implicitSpringDamper>
    <provideFeedback>true</provideFeedback>
  </gazebo>
  <gazebo reference="panda_joint1">
    <implicitSpringDamper>1</implicitSpringDamper>
    <provideFeedback>true</provideFeedback>
  </gazebo>
  <gazebo reference="panda_joint2">
    <implicitSpringDamper>1</implicitSpringDamper>
    <provideFeedback>true</provideFeedback>
  </gazebo>
  <gazebo reference="panda_joint3">
    <implicitSpringDamper>1</implicitSpringDamper>
    <provideFeedback>true</provideFeedback>
  </gazebo>
  <gazebo reference="panda_joint4">
    <implicitSpringDamper>1</implicitSpringDamper>
    <provideFeedback>true</provideFeedback>
  </gazebo>
  <gazebo reference="panda_joint5">
    <implicitSpringDamper>1</implicitSpringDamper>
    <provideFeedback>true</provideFeedback>
  </gazebo>
  <gazebo reference="panda_joint6">
    <implicitSpringDamper>1</implicitSpringDamper>
    <provideFeedback>true</provideFeedback>
  </gazebo>
  <gazebo reference="panda_finger_joint1">
    <implicitSpringDamper>1</implicitSpringDamper>
    <provideFeedback>true</provideFeedback>
  </gazebo>
  <gazebo reference="panda_finger_joint2">
    <implicitSpringDamper>1</implicitSpringDamper>
    <provideFeedback>true</provideFeedback>
  </gazebo>
  <!-- Adding FT sensor at wrist. This is not present in real robot and is used only for computing end-point effort directly, unlike in the real robot where it is estimated from the joint efforts. -->
  <gazebo reference="panda_joint7">
    <disableFixedJointLumping>true</disableFixedJointLumping>
    <sensor name="panda_joint7_force_torque" type="force_torque">
      <always_on>true</always_on>
      <visualize>false</visualize>
      <force_torque>
        <frame>sensor</frame>
        <measure_direction>child_to_parent</measure_direction>
      </force_torque>
    </sensor>
  </gazebo>
  <gazebo>
    <plugin filename="libgazebo_ros_ft_sensor.so" name="ft_sensor">
      <updateRate>30.0</updateRate>
      <topicName>/gazebo/robot/wrist/ft</topicName>
      <jointName>panda_joint7</jointName>
    </plugin>
  </gazebo>
  <gazebo>
    <plugin filename="libgazebo_ros_control.so" name="gazebo_ros_control">
      <robotNamespace>/</robotNamespace>
      <robotSimType>gazebo_ros_control/DefaultRobotHWSim</robotSimType>
      <legacyModeNS>true</legacyModeNS>
    </plugin>
  </gazebo>
  <transmission name="panda_tran_1">
    <type>transmission_interface/SimpleTransmission</type>
    <joint name="panda_joint1">
      <hardwareInterface>hardware_interface/EffortJointInterface</hardwareInterface>
    </joint>
    <actuator name="panda_motor_1">
      <hardwareInterface>hardware_interface/EffortJointInterface</hardwareInterface>
      <mechanicalReduction>1</mechanicalReduction>
    </actuator>
  </transmission>
  <transmission name="panda_tran_2">
    <type>transmission_interface/SimpleTransmission</type>
    <joint name="panda_joint2">
      <hardwareInterface>hardware_interface/EffortJointInterface</hardwareInterface>
    </joint>
    <actuator name="panda_motor_2">
      <hardwareInterface>hardware_interface/EffortJointInterface</hardwareInterface>
      <mechanicalReduction>1</mechanicalReduction>
    </actuator>
  </transmission>
  <transmission name="panda_tran_3">
    <type>transmission_interface/SimpleTransmission</type>
    <joint name="panda_joint3">
      <hardwareInterface>hardware_interface/EffortJointInterface</hardwareInterface>
    </joint>
    <actuator name="panda_motor_3">
      <hardwareInterface>hardware_interface/EffortJointInterface</hardwareInterface>
      <mechanicalReduction>1</mechanicalReduction>
    </actuator>
  </transmission>
  <transmission name="panda_tran_4">
    <type>transmission_interface/SimpleTransmission</type>
    <joint name="panda_joint4">
      <hardwareInterface>hardware_interface/EffortJointInterface</hardwareInterface>
    </joint>
    <actuator name="panda_motor_4">
      <hardwareInterface>hardware_interface/EffortJointInterface</hardwareInterface>
      <mechanicalReduction>1</mechanicalReduction>
    </actuator>
  </transmission>
  <transmission name="panda_tran_5">
    <type>transmission_interface/SimpleTransmission</type>
    <joint name="panda_joint5">
      <hardwareInterface>hardware_interface/EffortJointInterface</hardwareInterface>
    </joint>
    <actuator name="panda_motor_5">
      <hardwareInterface>hardware_interface/EffortJointInterface</hardwareInterface>
      <mechanicalReduction>1</mechanicalReduction>
    </actuator>
  </transmission>
  <transmission name="panda_tran_6">
    <type>transmission_interface/SimpleTransmission</type>
    <joint name="panda_joint6">
      <hardwareInterface>hardware_interface/EffortJointInterface</hardwareInterface>
    </joint>
    <actuator name="panda_motor_6">
      <hardwareInterface>hardware_interface/EffortJointInterface</hardwareInterface>
      <mechanicalReduction>1</mechanicalReduction>
    </actuator>
  </transmission>
  <transmission name="panda_tran_7">
    <type>transmission_interface/SimpleTransmission</type>
    <joint name="panda_joint7">
      <hardwareInterface>hardware_interface/EffortJointInterface</hardwareInterface>
    </joint>
    <actuator name="panda_motor_7">
      <hardwareInterface>hardware_interface/EffortJointInterface</hardwareInterface>
      <mechanicalReduction>1</mechanicalReduction>
    </actuator>
  </transmission>
  <transmission name="panda_leftfinger">
    <type>transmission_interface/SimpleTransmission</type>
    <joint name="panda_finger_joint1">
      <hardwareInterface>hardware_interface/EffortJointInterface</hardwareInterface>
    </joint>
    <actuator name="panda_finger_joint1">
      <hardwareInterface>hardware_interface/EffortJointInterface</hardwareInterface>
      <mechanicalReduction>1</mechanicalReduction>
    </actuator>
  </transmission>
  <transmission name="panda_rightfinger">
    <type>transmission_interface/SimpleTransmission</type>
    <joint name="panda_finger_joint2">
      <hardwareInterface>hardware_interface/EffortJointInterface</hardwareInterface>
    </joint>
    <actuator name="panda_finger_joint2">
      <hardwareInterface>hardware_interface/EffortJointInterface</hardwareInterface>
      <mechanicalReduction>1</mechanicalReduction>
    </actuator>
  </transmission>
  <!-- NAO AND PROJECTOR -->
  <joint name="darko/nao_base_joint" type="fixed">
    <origin rpy="0 0 0" xyz="0.43 0 0.01"/>
    <parent link="darko/platform_2_link"/>
    <child link="darko/nao_link"/>
  </joint>
  <link name="darko/nao_link">
    <visual>
      <origin rpy="0 0 1.5707963267948966" xyz="0 0 0"/>
      <geometry>
        <mesh filename="package://darko_description/meshes/nao_sitting.dae"/>
      </geometry>
    </visual>
    <collision>
      <origin rpy="0 0 1.5707963267948966" xyz="0 0 0"/>
      <geometry>
        <mesh filename="package://darko_description/meshes/nao_sitting.dae"/>
      </geometry>
    </collision>
    <inertial>
      <origin rpy="0 0 1.5707963267948966" xyz="0 0 0"/>
      <mass value="3.5"/>
      <inertia ixx="0.10791666666666666" ixy="0" ixz="0" iyy="0.02916666666666667" iyz="0" izz="0.13124999999999998"/>
    </inertial>
  </link>
  <joint name="darko/projector_base_joint" type="fixed">
    <origin rpy="0 1.571 0" xyz="0.38 0 -0.17"/>
    <parent link="darko/platform_1_link"/>
    <child link="darko/projector_base_link"/>
  </joint>
  <link name="darko/projector_base_link">
    <visual>
      <origin rpy="0 0 0" xyz="0 0 0"/>
      <geometry>
        <mesh filename="package://darko_description/meshes/projector.dae"/>
      </geometry>
    </visual>
    <collision>
      <origin rpy="0 0 0" xyz="0 0 0"/>
      <geometry>
        <mesh filename="package://darko_description/meshes/projector.dae"/>
      </geometry>
    </collision>
    <inertial>
      <origin rpy="0 0 0" xyz="0.0 0.0 0"/>
      <mass value="5.0"/>
      <inertia ixx="0.043500000000000004" ixy="0" ixz="0" iyy="0.075" iyz="0" izz="0.043500000000000004"/>
    </inertial>
  </link>
  <joint name="darko/projector_joint" type="fixed">
    <parent link="darko/projector_base_link"/>
    <child link="darko/projector_link"/>
    <origin rpy="0 0 0" xyz="0 0 0"/>
  </joint>
  <link name="darko/projector_link"/>
  <!-- COMPUTERS AND WIRELESS E-STOP -->
  <joint name="darko/wireless_estop_receiver_base_joint" type="fixed">
    <origin rpy="0 0 1.571" xyz="-0.2 0.17 0"/>
    <parent link="darko/platform_1_link"/>
    <child link="darko/wireless_estop_receiver_base_link"/>
  </joint>
  <link name="darko/wireless_estop_receiver_base_link">
    <visual>
      <origin rpy="0 0 0" xyz="0 0 0"/>
      <geometry>
        <mesh filename="package://darko_description/meshes/tyro_gemini.dae"/>
      </geometry>
    </visual>
    <collision>
      <origin rpy="0 0 0" xyz="0 0 0"/>
      <geometry>
        <mesh filename="package://darko_description/meshes/tyro_gemini.dae"/>
      </geometry>
    </collision>
    <inertial>
      <origin rpy="0 0 0" xyz="0.0 0.0 0"/>
      <mass value="0.5"/>
      <inertia ixx="0.002266666666666667" ixy="0" ixz="0" iyy="0.003333333333333334" iyz="0" izz="0.002266666666666667"/>
    </inertial>
  </link>
  <joint name="darko/wireless_estop_receiver_joint" type="fixed">
    <parent link="darko/wireless_estop_receiver_base_link"/>
    <child link="darko/wireless_estop_receiver_link"/>
    <origin rpy="0 0 0" xyz="0 0 0"/>
  </joint>
  <link name="darko/wireless_estop_receiver_link"/>
  <joint name="darko/mini_gaming_pc_base_joint" type="fixed">
    <origin rpy="0 0 0" xyz="0.2 0.14 0"/>
    <parent link="darko/platform_1_link"/>
    <child link="darko/mini_gaming_pc_base_link"/>
  </joint>
  <link name="darko/mini_gaming_pc_base_link">
    <visual>
      <origin rpy="0 0 0" xyz="0 0 0"/>
      <geometry>
        <mesh filename="package://darko_description/meshes/mini_pc_v3.dae"/>
      </geometry>
    </visual>
    <collision>
      <origin rpy="0 0 0" xyz="0 0 0"/>
      <geometry>
        <mesh filename="package://darko_description/meshes/mini_pc_v3.dae"/>
      </geometry>
    </collision>
    <inertial>
      <origin rpy="0 0 0" xyz="0.0 0.0 0"/>
      <mass value="3.0"/>
      <inertia ixx="0.012500000000000002" ixy="0" ixz="0" iyy="0.020000000000000004" iyz="0" izz="0.012500000000000002"/>
    </inertial>
  </link>
  <joint name="darko/mini_gaming_pc_joint" type="fixed">
    <parent link="darko/mini_gaming_pc_base_link"/>
    <child link="darko/mini_gaming_pc_link"/>
    <origin rpy="0 0 0" xyz="0 0 0"/>
  </joint>
  <link name="darko/mini_gaming_pc_link"/>
  <joint name="darko/xavier_agx_base_joint" type="fixed">
    <origin rpy="0 0 0" xyz="0.2 -0.15 0"/>
    <parent link="darko/platform_1_link"/>
    <child link="darko/xavier_agx_base_link"/>
  </joint>
  <link name="darko/xavier_agx_base_link">
    <visual>
      <origin rpy="0 0 0" xyz="0 0 0"/>
      <geometry>
        <mesh filename="package://darko_description/meshes/xavier_agx_dk.dae"/>
      </geometry>
    </visual>
    <collision>
      <origin rpy="0 0 0" xyz="0 0 0"/>
      <geometry>
        <mesh filename="package://darko_description/meshes/xavier_agx_dk.dae"/>
      </geometry>
    </collision>
    <inertial>
      <origin rpy="0 0 0" xyz="0.0 0.0 0"/>
      <mass value="1.0"/>
      <inertia ixx="0.0020333333333333336" ixy="0" ixz="0" iyy="0.0024" iyz="0" izz="0.0020333333333333336"/>
    </inertial>
  </link>
  <joint name="darko/xavier_agx_joint" type="fixed">
    <parent link="darko/xavier_agx_base_link"/>
    <child link="darko/xavier_agx_link"/>
    <origin rpy="0 0 0" xyz="0 0 0"/>
  </joint>
  <link name="darko/xavier_agx_link"/>
</robot>
